<?xml version="1.0" ?>
<!-- =================================================================================== -->
<!-- |    This document was autogenerated by xacro from robot.urdf.xacro               | -->
<!-- |    EDITING THIS FILE BY HAND IS NOT RECOMMENDED                                 | -->
<!-- =================================================================================== -->
<robot name="3dof_robot">
  <!-- Material Definitions -->
  <!-- Modern metallic silver for base and primary structure -->
  <material name="metallic_silver">
    <color rgba="0.8 0.8 0.85 1.0"/>
  </material>
  <!-- Deep orange accent for dynamic parts -->
  <material name="deep_orange">
    <color rgba="0.95 0.45 0.15 1.0"/>
  </material>
  <!-- Sleek dark gray for secondary parts -->
  <material name="sleek_gray">
    <color rgba="0.25 0.25 0.25 1.0"/>
  </material>
  <!-- Electric blue for joints and end-effector -->
  <material name="electric_blue">
    <color rgba="0.2 0.5 1.0 1.0"/>
  </material>
  <!-- Metallic white for highlights -->
  <material name="metallic_white">
    <color rgba="0.95 0.95 0.95 1.0"/>
  </material>
  <!-- End effector radius -->
  <!-- End effector length -->
  <!-- End effector mass -->
  <!-- Base -->
  <link name="world"/>
  <link name="base_link">
    <visual>
      <origin rpy="0 0 0" xyz="0 0 0.01"/>
      <geometry>
        <box size="0.2 0.2 0.02"/>
      </geometry>
      <material name="sleek_gray"/>
    </visual>
    <collision>
      <origin rpy="0 0 0" xyz="0 0 0.01"/>
      <geometry>
        <box size="0.2 0.2 0.02"/>
      </geometry>
    </collision>
    <inertial>
      <origin rpy="0 0 0" xyz="0 0 0.01"/>
      <mass value="2.0"/>
      <inertia ixx="0.01" ixy="0" ixz="0" iyy="0.01" iyz="0" izz="0.01"/>
    </inertial>
  </link>
  <joint name="world_to_base" type="fixed">
    <parent link="world"/>
    <child link="base_link"/>
    <origin rpy="0 0 0" xyz="0 0 0"/>
  </joint>
  <link name="link_1">
    <inertial>
      <origin rpy="0 0 0" xyz="0 0 0.125"/>
      <mass value="0.8"/>
      <inertia ixx="0.004281866666666666" ixy="0" ixz="0" iyy="0.004281866666666666" iyz="0" izz="0.00023040000000000002"/>
    </inertial>
    <visual>
      <origin rpy="0 0 0" xyz="0 0 0.125"/>
      <geometry>
        <cylinder length="0.25" radius="0.024"/>
      </geometry>
      <material name="metallic_silver"/>
    </visual>
    <collision>
      <origin rpy="0 0 0" xyz="0 0 0.125"/>
      <geometry>
        <cylinder length="0.25" radius="0.024"/>
      </geometry>
    </collision>
  </link>
  <joint name="base_to_link_1" type="fixed">
    <parent link="base_link"/>
    <child link="link_1"/>
    <origin rpy="0 0 0" xyz="0 0 0.02"/>
  </joint>
  <link name="link_2">
    <inertial>
      <origin rpy="0 0 0" xyz="0 0 0.075"/>
      <mass value="0.6"/>
      <inertia ixx="0.0011849999999999999" ixy="0" ixz="0" iyy="0.0011849999999999999" iyz="0" izz="0.00012"/>
    </inertial>
    <visual>
      <origin rpy="0 0 0" xyz="0 0 0.075"/>
      <geometry>
        <cylinder length="0.15" radius="0.02"/>
      </geometry>
      <material name="deep_orange"/>
    </visual>
    <collision>
      <origin rpy="0 0 0" xyz="0 0 0.075"/>
      <geometry>
        <cylinder length="0.15" radius="0.02"/>
      </geometry>
    </collision>
  </link>
  <joint name="link_1_to_link_2" type="revolute">
    <parent link="link_1"/>
    <child link="link_2"/>
    <origin rpy="0 0 0" xyz="0 0 0.25"/>
    <axis xyz="0 1 0"/>
    <limit effort="50" lower="-1.57" upper="1.57" velocity="1.0"/>
  </joint>
  <link name="joint_1_visual">
    <visual>
      <origin rpy="0 0 0" xyz="0 0 0"/>
      <geometry>
        <cylinder length="0.06" radius="0.035"/>
      </geometry>
      <material name="electric_blue"/>
    </visual>
  </link>
  <joint name="joint_1_visual_joint" type="fixed">
    <parent link="link_1"/>
    <child link="joint_1_visual"/>
    <origin rpy="1.570796326795 0 0" xyz="0 0 0.25"/>
  </joint>
  <link name="link_3">
    <inertial>
      <origin rpy="0 0 0" xyz="0 0 0.075"/>
      <mass value="0.4"/>
      <inertia ixx="0.0007899999999999999" ixy="0" ixz="0" iyy="0.0007899999999999999" iyz="0" izz="8e-05"/>
    </inertial>
    <visual>
      <origin rpy="0 0 0" xyz="0 0 0.075"/>
      <geometry>
        <cylinder length="0.15" radius="0.02"/>
      </geometry>
      <material name="metallic_silver"/>
    </visual>
    <collision>
      <origin rpy="0 0 0" xyz="0 0 0.075"/>
      <geometry>
        <cylinder length="0.15" radius="0.02"/>
      </geometry>
    </collision>
  </link>
  <joint name="link_2_to_link_3" type="revolute">
    <parent link="link_2"/>
    <child link="link_3"/>
    <origin rpy="0 0 0" xyz="0 0 0.15"/>
    <axis xyz="0 1 0"/>
    <limit effort="50" lower="-1.57" upper="1.57" velocity="1.0"/>
  </joint>
  <link name="joint_2_visual">
    <visual>
      <origin rpy="0 0 0" xyz="0 0 0"/>
      <geometry>
        <cylinder length="0.05" radius="0.02"/>
      </geometry>
      <material name="electric_blue"/>
    </visual>
  </link>
  <joint name="joint_2_visual_joint" type="fixed">
    <parent link="link_2"/>
    <child link="joint_2_visual"/>
    <origin rpy="1.570796326795 0 0" xyz="0 0 0.15"/>
  </joint>
  <link name="link_4">
    <inertial>
      <origin rpy="0 0 0" xyz="0 0 0.05"/>
      <mass value="0.3"/>
      <inertia ixx="0.000266875" ixy="0" ixz="0" iyy="0.000266875" iyz="0" izz="3.3749999999999994e-05"/>
    </inertial>
    <visual>
      <origin rpy="0 0 0" xyz="0 0 0.05"/>
      <geometry>
        <cylinder length="0.1" radius="0.015"/>
      </geometry>
      <material name="deep_orange"/>
    </visual>
    <collision>
      <origin rpy="0 0 0" xyz="0 0 0.05"/>
      <geometry>
        <cylinder length="0.1" radius="0.015"/>
      </geometry>
    </collision>
  </link>
  <joint name="link_3_to_link_4" type="revolute">
    <parent link="link_3"/>
    <child link="link_4"/>
    <origin rpy="0 0 0" xyz="0 0 0.15"/>
    <axis xyz="0 1 0"/>
    <limit effort="50" lower="-1.57" upper="1.57" velocity="1.0"/>
  </joint>
  <link name="joint_3_visual">
    <visual>
      <origin rpy="0 0 0" xyz="0 0 0"/>
      <geometry>
        <cylinder length="0.04" radius="0.02"/>
      </geometry>
      <material name="electric_blue"/>
    </visual>
  </link>
  <joint name="joint_3_visual_joint" type="fixed">
    <parent link="link_3"/>
    <child link="joint_3_visual"/>
    <origin rpy="1.570796326795 0 0" xyz="0 0 0.15"/>
  </joint>
  <!-- Gripper -->
  <link name="gripper_base">
    <visual>
      <origin rpy="0 0 0" xyz="0 0 0.01"/>
      <geometry>
        <box size="0.04 0.03 0.02"/>
      </geometry>
      <material name="sleek_gray"/>
    </visual>
    <collision>
      <origin rpy="0 0 0" xyz="0 0 0.01"/>
      <geometry>
        <box size="0.04 0.03 0.02"/>
      </geometry>
    </collision>
    <inertial>
      <origin rpy="0 0 0" xyz="0 0 0.01"/>
      <mass value="0.1"/>
      <inertia ixx="1e-4" ixy="0" ixz="0" iyy="1e-4" iyz="0" izz="1e-4"/>
    </inertial>
    <!-- Fingers -->
    <visual>
      <origin rpy="0 0 0" xyz="0.02 0 0.035"/>
      <geometry>
        <box size="0.01 0.015 0.05"/>
      </geometry>
      <material name="metallic_white"/>
    </visual>
    <collision>
      <origin rpy="0 0 0" xyz="0.02 0 0.035"/>
      <geometry>
        <box size="0.01 0.015 0.05"/>
      </geometry>
    </collision>
    <visual>
      <origin rpy="0 0 0" xyz="-0.02 0 0.035"/>
      <geometry>
        <box size="0.01 0.015 0.05"/>
      </geometry>
      <material name="metallic_white"/>
    </visual>
    <collision>
      <origin rpy="0 0 0" xyz="-0.02 0 0.035"/>
      <geometry>
        <box size="0.01 0.015 0.05"/>
      </geometry>
    </collision>
  </link>
  <joint name="link_4_to_gripper" type="revolute">
    <parent link="link_4"/>
    <child link="gripper_base"/>
    <origin rpy="0 0 0" xyz="0 0 0.1"/>
    <axis xyz="0 1 0"/>
    <limit effort="50" lower="-1.57" upper="1.57" velocity="1.0"/>
  </joint>
  <link name="joint_4_visual">
    <visual>
      <origin rpy="0 0 0" xyz="0 0 0"/>
      <geometry>
        <cylinder length="0.04" radius="0.013"/>
      </geometry>
      <material name="electric_blue"/>
    </visual>
  </link>
  <joint name="joint_4_visual_joint" type="fixed">
    <parent link="link_4"/>
    <child link="joint_4_visual"/>
    <origin rpy="1.570796326795 0 0" xyz="0 0 0.1"/>
  </joint>
</robot>
